<?xml version="1.0"?>
<robot name="irb140_robot">

  <!-- World fixed link -->
  <link name="world"></link>
  <link name="base_link">
		<visual>
			<origin rpy="0 0 0" xyz="0 0 0" />
			<geometry>
				<mesh filename="package://irb140_sim/meshes/irb140/visual/base_link.stl" scale="0.01 0.01 0.01" />
			</geometry>
			<material name="abb_orange">
				<color rgba="1 0.43 0 1" />
			</material>
		</visual>
		<collision>
			<origin rpy="0 0 0" xyz="0 0 0" />
			<geometry>
				<mesh filename="package://irb140_layout/meshes/irb140/collision_low_poly/base_link.stl" scale="0.01 0.01 0.01" />
			</geometry>
			<material name="yellow">
				<color rgba="0 1 1 1" />
			</material>
		</collision>
		<inertial>
			<mass value="26.36" />
			<origin xyz="-0.0820 0.0004 0.0599" rpy="0 0 0" />
			<inertia ixx="0.222" ixy="0" ixz="0.0156" iyy="0.3553" iyz="0.0017" izz="0.5236" />
		</inertial>
	</link>
  <joint name="world_fixed" type="fixed">
    <origin xyz="0.0 0.0 0.0" rpy="0.0 0.0 0.0"/>
    <parent link="world"/>
    <child link="base_link"/>
  </joint>

  <!-- Link 1 -->
  <link name="link_1">
		<visual>
			<origin rpy="0 0 0" xyz="0 0 0" />
			<geometry>
				<mesh filename="package://irb140_layout/meshes/irb140/visual/link_1.stl" scale="0.01 0.01 0.01" />
			</geometry>
			<material name="abb_orange">
				<color rgba="1 0.43 0 1" />
			</material>
		</visual>
		<collision>
			<origin rpy="0 0 0" xyz="0 0 0" />
			<geometry>
				<mesh filename="package://irb140_layout/meshes/irb140/collision_low_poly/link_1.stl" scale="0.01 0.01 0.01" />
			</geometry>
			<material name="yellow">
				<color rgba="0 1 1 1" />
			</material>
		</collision>
		<inertial>
			<mass value="34.56" />
			<origin xyz="0.0281 0.0438 0.2634" rpy="0 0 0" />
			<inertia ixx="0.5087" ixy="-0.0014" ixz="-0.0524" iyy="0.4612" iyz="-0.0688" izz="0.4567" />
		</inertial>
	</link>
  <joint name="joint_1" type="revolute">
		<origin rpy="0 0 0" xyz="0 0 0" />
		<parent link="base_link" />
		<child link="link_1" />
		<axis xyz="0 0 1" />
		<limit effort="1000" lower="-3.1416" upper="3.1416" velocity="2.618" />
	</joint>
  <transmission name="trans_joint_1">
    <type>transmission_interface/SimpleTransmission</type>
    <joint name="joint_1">
      <hardwareInterface>hardware_interface/PositionJointInterface </hardwareInterface > 
    </joint >
    <actuator name="motor_joint_1">
      <mechanicalReduction>1</mechanicalReduction>
    </actuator> 
  </transmission>

  <!-- Link 2 -->
  <link name="link_2">
		<visual>
			<origin rpy="0 0 0" xyz="-0.07 0 -0.352" />
			<geometry>
				<mesh filename="package://irb140_layout/meshes/irb140/visual/link_2.stl" scale="0.01 0.01 0.01" />
			</geometry>
			<material name="abb_orange">
				<color rgba="1 0.43 0 1" />
			</material>
		</visual>
		<collision>
			<origin rpy="0 0 0" xyz="-0.07 0 -0.352" />
			<geometry>
				<mesh filename="package://irb140_layout/meshes/irb140/collision_low_poly/link_2.stl" scale="0.01 0.01 0.01" />
			</geometry>
			<material name="yellow">
				<color rgba="0 1 1 1" />
			</material>
		</collision>
		<inertial>
			<mass value="15.99" />
			<origin xyz="-0.0097 -0.0924 0.1983" rpy="0 0 0" />
			<inertia ixx="0.3286" ixy="0.0010" ixz="-0.0038" iyy="0.2775" iyz="0.0379" izz="0.0948" />
		</inertial>
	</link>
  <joint name="joint_2" type="revolute">
		<origin rpy="0 0 0" xyz="0.070 0 0.352" />
		<parent link="link_1" />
		<child link="link_2" />
		<axis xyz="0 1 0" />
		<limit effort="1000" lower="-0.7853" upper="1.5708" velocity="2.618" />
	</joint>
  <transmission name="trans_joint_2">
    <type>transmission_interface/SimpleTransmission</type>
    <joint name="joint_2">
      <hardwareInterface>hardware_interface/PositionJointInterface </hardwareInterface > 
    </joint >
    <actuator name="motor_joint_2">
      <mechanicalReduction>1</mechanicalReduction>
    </actuator> 
  </transmission>

<!-- Link 3 -->
  <link name="link_3">
		<visual>
			<origin rpy="0 0 0" xyz="-0.07 0.065 -0.712" />
			<geometry>
				<mesh filename="package://irb140_layout/meshes/irb140/visual/link_3.stl" scale="0.01 0.01 0.01" />
			</geometry>
			<material name="abb_orange">
				<color rgba="1 0.43 0 1" />
			</material>
		</visual>
		<collision>
			<origin rpy="0 0 0" xyz="-0.07 0.065 -0.712" />
			<geometry>
				<mesh filename="package://irb140_layout/meshes/irb140/collision_low_poly/link_3.stl" scale="0.01 0.01 0.01" />
			</geometry>
			<material name="yellow">
				<color rgba="0 1 1 1" />
			</material>
		</collision>
		<inertial>
			<mass value="16.9793" />
			<origin xyz="0.0196 0.0725 -0.0057" rpy="0 0 0" />
			<inertia ixx="0.0682" ixy="0.0063" ixz="0.004" iyy="0.1990" iyz="0.0007" izz="0.1823" />
		</inertial>
	</link>
  <joint name="joint_3" type="revolute">
		<origin rpy="0 0 0" xyz="0 -0.065 0.360" />
		<parent link="link_2" />
		<child link="link_3" />
		<axis xyz="0 1 0" />
		<limit effort="1000" lower="-2.4434" upper="0.8726" velocity="2.618" />
	</joint>
  <transmission name="trans_joint_3">
    <type>transmission_interface/SimpleTransmission</type>
    <joint name="joint_3">
      <hardwareInterface>hardware_interface/PositionJointInterface </hardwareInterface > 
    </joint >
    <actuator name="motor_joint_3">
      <mechanicalReduction>1</mechanicalReduction>
    </actuator> 
  </transmission>
  
  <!-- Link 4 -->
  <link name="link_4">
		<visual>
			<origin rpy="0 0 0" xyz="-0.309 0 -0.712" />
			<geometry>
				<mesh filename="package://irb140_layout/meshes/irb140/visual/link_4.stl" scale="0.01 0.01 0.01" />
			</geometry>
			<material name="abb_orange">
				<color rgba="1 0.43 0 1" />
			</material>
		</visual>
		<collision>
			<origin rpy="0 0 0" xyz="-0.309 0 -0.712" />
			<geometry>
				<mesh filename="package://irb140_layout/meshes/irb140/collision_low_poly/link_4.stl" scale="0.01 0.01 0.01" />
			</geometry>
			<material name="yellow">
				<color rgba="0 1 1 1" />
			</material>
		</collision>
		<inertial>
			<mass value="3.7398" />
			<origin xyz="0.0726 -0.0012 -0.0014" rpy="0 0 0" />
			<inertia ixx="0.0073" ixy="0.0004" ixz="-0.0001" iyy="0.0153" iyz="0" izz="0.0172" />
		</inertial>
	</link>
  <joint name="joint_4" type="revolute">
		<origin rpy="0 0 0" xyz="0.239 0.065 0" />
		<parent link="link_3" />
		<child link="link_4" />
		<axis xyz="1 0 0" />
		<limit effort="1000" lower="-3.49" upper="3.49" velocity="6.2832" />
	</joint>
  <transmission name="trans_joint_4">
    <type>transmission_interface/SimpleTransmission</type>
    <joint name="joint_4">
      <hardwareInterface>hardware_interface/PositionJointInterface </hardwareInterface > 
    </joint >
    <actuator name="motor_joint_4">
      <mechanicalReduction>1</mechanicalReduction>
    </actuator> 
  </transmission>

  <!-- Link 5 -->
  <link name="link_5">
		<visual>
			<origin rpy="0 0 0" xyz="-0.450 0 -0.712" />
			<geometry>
				<mesh filename="package://irb140_layout/meshes/irb140/visual/link_5.stl" scale="0.01 0.01 0.01" />
			</geometry>
			<material name="abb_orange">
				<color rgba="1 0.43 0 1" />
			</material>
		</visual>
		<collision>
			<origin rpy="0 0 0" xyz="-0.450 0 -0.712" />
			<geometry>
				<mesh filename="package://irb140_layout/meshes/irb140/collision_low_poly/link_5.stl" scale="0.01 0.01 0.01" />
			</geometry>
			<material name="yellow">
				<color rgba="0 1 1 1" />
			</material>
		</collision>
		<inertial>
			<mass value="0.3039" />
			<origin xyz="-0.0014 0.0006 -0.0002" rpy="0 0 0" />
			<inertia ixx="0.001" ixy="0" ixz="0" iyy="0.002" iyz="0" izz="0.001" />
		</inertial>
	</link>
  <joint name="joint_5" type="revolute">
		<origin rpy="0 0 0" xyz="0.141 0 0" />
		<parent link="link_4" />
		<child link="link_5" />
		<axis xyz="0 1 0" />
		<limit effort="1000" lower="-2.0071" upper="2.0071" velocity="6.2832" />
	</joint>
	<transmission name="trans_joint_5">
		<type>transmission_interface/SimpleTransmission</type>
		<joint name="joint_5">
			<hardwareInterface>hardware_interface/PositionJointInterface</hardwareInterface>
		</joint>
		<actuator name="motor_joint_5">
			<mechanicalReduction>1</mechanicalReduction>
		</actuator>
	</transmission>

  <!-- Link 6 -->
  <link name="link_6">
		<visual>
			<origin rpy="0 0 0" xyz="-0.515 0 -0.712" />
			<geometry>
				<mesh filename="package://irb140_layout/meshes/irb140/visual/link_6.stl" scale="0.01 0.01 0.01" />
			</geometry>
			<material name="abb_orange">
				<color rgba="1 0.43 0 1" />
			</material>
		</visual>
		<collision>
			<origin rpy="0 0 0" xyz="-0.515 0 -0.712" />
			<geometry>
				<mesh filename="package://irb140_layout/meshes/irb140/collision_low_poly/link_6.stl" scale="0.01 0.01 0.01" />
			</geometry>
			<material name="yellow">
				<color rgba="0 1 1 1" />
			</material>
		</collision>
		<inertial>
			<mass value="0.0549" />
			<origin xyz="-0.013 0 0" rpy="0 0 0" />
			<inertia ixx="0.00001" ixy="0" ixz="0" iyy="0.00001" iyz="0" izz="0.00001" />
		</inertial>
	</link>
  <joint name="joint_6" type="revolute">
		<origin rpy="0 0 0" xyz="0.065 0 0" />
		<parent link="link_5" />
		<child link="link_6" />
		<axis xyz="1 0 0" />
		<limit effort="1000" lower="-6.9813" upper="6.9813" velocity="1" />
	</joint>
	<transmission name="trans_joint_6">
		<type>transmission_interface/SimpleTransmission</type>
		<joint name="joint_6">
			<hardwareInterface>hardware_interface/PositionJointInterface</hardwareInterface>
		</joint>
		<actuator name="motor_joint_6">
			<mechanicalReduction>1</mechanicalReduction>
		</actuator>
	</transmission>

  <!-- Gripper -->
  <link name="gripper_body">
    <inertial>
      <mass value="0.1" />
      <origin rpy="0 0 0" xyz="0 0 0" />
      <inertia ixx="0.13292157" ixy="0.0" ixz="0" iyy="0.8980362" iyz="0" izz="0.6991288" />
    </inertial>
    <collision>
      <origin rpy="0 0 0" xyz="0 0 0" />
      <geometry>
        <mesh filename="package://irb140_layout/meshes/gripper/mesh_cuerpo.stl" scale="0.001 0.001 0.001" />
      </geometry>
    </collision>
    <visual>
      <origin rpy="0 0 0" xyz="0 0 0" />
      <geometry>
        <mesh filename="package://irb140_layout/meshes/gripper/mesh_cuerpo.stl" scale="0.001 0.001 0.001" />
      </geometry>
      <material name="gris">
        <color rgba="0.5 0.5 0.5 1" />
      </material>
    </visual>
  </link>
  <joint name="link_6__gripper_body" type="fixed">
		<parent link="link_6" />
		<child link="gripper_body" />
		<origin rpy="0 1.57 0" xyz="0 0 0" />
	</joint>
 
  <link name="left_ext">
    <inertial>
      <mass value="0.1" />
      <origin rpy="0 0 0" xyz="0 0 0" />
      <inertia ixx="0.0000847702" ixy="0" ixz="0" iyy="0.0000955040" iyz="0" izz="0.0000331406" />
    </inertial>
    <collision>
      <origin rpy="0 0 0" xyz="0 0 0" />
      <geometry>
        <mesh filename="package://irb140_layout/meshes/gripper/mesh_eslabon_externo.stl" scale="0.001 0.001 0.001" />
      </geometry>
    </collision>
    <visual>
      <origin rpy="0 0 0" xyz="0 0 0" />
      <geometry>
        <mesh filename="package://irb140_layout/meshes/gripper/mesh_eslabon_externo.stl" scale="0.001 0.001 0.001" />
      </geometry>
      <material name="blu">
        <color rgba="0 0 1 1" />
      </material>
    </visual>
  </link>
  <joint name="gripper_body__left_ext" type="fixed">
    <origin rpy="0 0 0" xyz="0.0 -0.046785 0.103" />
    <parent link="gripper_body" />
    <child link="left_ext" />
  </joint>

  <link name="left_int">
    <inertial>
      <mass value="0.1" />
      <origin rpy="0 0 0" xyz="-0.031 0 0.04" />
      <inertia ixx="0.0000213613" ixy="0" ixz="0" iyy="0.0000595838" iyz="0" izz="0.0000394382" />
    </inertial>
    <collision>
      <origin rpy="0 0 0" xyz="0 0 0" />
      <geometry>
        <mesh filename="package://irb140_layout/meshes/gripper/mesh_eslabon_interno.stl" scale="0.001 0.001 0.001" />
      </geometry>
    </collision>
    <visual>
      <origin rpy="0 0 0" xyz="0 0 0" />
      <geometry>
        <mesh filename="package://irb140_layout/meshes/gripper/mesh_eslabon_interno.stl" scale="0.001 0.001 0.001" />
      </geometry>
      <material name="blug">
        <color rgba="0 1 1 1" />
      </material>
    </visual>
  </link>
  <joint name="gripper_body__left_int" type="fixed">
    <origin rpy="0 0 0" xyz="0.0 -0.026 0.115" />
    <parent link="gripper_body" />
    <child link="left_int" />
  </joint>

  <link name="right_ext">
    <inertial>
      <mass value="0.1" />
      <origin rpy="0 0 0" xyz="0 0 0" />
      <inertia ixx="0.0000847702" ixy="0" ixz="0" iyy="0.0000955040" iyz="0" izz="0.0000331406" />
    </inertial>
    <collision>
      <origin rpy="0 0 0" xyz="0 0 0" />
      <geometry>
        <mesh filename="package://irb140_layout/meshes/gripper/mesh_eslabon_externo.stl" scale="0.001 0.001 0.001" />
      </geometry>
    </collision>
    <visual>
      <origin rpy="0 0 0" xyz="0 0 0" />
      <geometry>
        <mesh filename="package://irb140_layout/meshes/gripper/mesh_eslabon_externo.stl" scale="0.001 0.001 0.001" />
      </geometry>
      <material name="blu">
        <color rgba="0 0 1 1" />
      </material>
    </visual>
  </link>
  <joint name="gripper_body__right_ext" type="fixed">
    <origin rpy="0 0 3.14" xyz="0 0.046785 0.103" />
    <parent link="gripper_body" />
    <child link="right_ext" />
  </joint>

  <link name="right_int">
    <inertial>
      <mass value="0.1" />
      <origin rpy="0 0 0" xyz="-0.031 0 0.04" />
      <inertia ixx="0.0000213613" ixy="0" ixz="0" iyy="0.0000595838" iyz="0" izz="0.0000394382" />
    </inertial>
    <collision>
      <origin rpy="0 0 0" xyz="0 0 0" />
      <geometry>
        <mesh filename="package://irb140_layout/meshes/gripper/mesh_eslabon_interno.stl" scale="0.001 0.001 0.001" />
      </geometry>
    </collision>
    <visual>
      <origin rpy="0 0 0" xyz="0 0 0" />
      <geometry>
        <mesh filename="package://irb140_layout/meshes/gripper/mesh_eslabon_interno.stl" scale="0.001 0.001 0.001" />
      </geometry>
      <material name="blug">
        <color rgba="0 1 1 1" />
      </material>
    </visual>
  </link>
    <joint name="gripper_body__right_int" type="fixed">
    <origin rpy="0 0 0" xyz="0.0 0.026 0.115" />
    <parent link="gripper_body" />
    <child link="right_int" />
  </joint>

  <!-- Fingers -->
  <link name="left_finger">
    <inertial>
      <mass value="0.1" />
      <origin rpy="0 0 0" xyz="0 0.018 0.032" />
      <inertia ixx="0.0000847702" ixy="0" ixz="0" iyy="0.0000955040" iyz="0" izz="0.0000331406" />
    </inertial>
    <collision>
      <!-- <origin rpy="0 0 0" xyz="0 -0.002 0" /> -->
      <origin rpy="0 0 0" xyz="0 0 0" />
      <geometry>
        <mesh filename="package://irb140_layout/meshes/gripper/mesh_dedo.stl" scale="0.001 0.001 0.001" />
      </geometry>
    </collision>
    <visual>
      <origin rpy="0 0 0" xyz="0 0 0" />
      <geometry>
        <mesh filename="package://irb140_layout/meshes/gripper/mesh_dedo.stl" scale="0.001 0.001 0.001" />
      </geometry>
      <material name="white">
        <color rgba="1 1 1 1" />
      </material>
    </visual>
  </link>
  <joint name="left_ext__left_finger" type="fixed">
    <origin rpy="0 0 0" xyz="0 0 0.080" />
    <parent link="left_ext" />
    <child link="left_finger" />
  </joint>

  <link name="right_finger">
    <inertial>
      <mass value="0.1" />
      <origin rpy="0 0 3.14" xyz="0 0.018 0.032" />
      <inertia ixx="0.0000847702" ixy="0" ixz="0" iyy="0.0000955040" iyz="0" izz="0.0000331406" />
    </inertial>
    <collision>
      <!-- <origin rpy="0 0 0" xyz="0 -0.002 0.0" /> -->
      <origin rpy="0 0 0" xyz="0 0 0" />
      <geometry>
        <mesh filename="package://irb140_layout/meshes/gripper/mesh_dedo.stl" scale="0.001 0.001 0.001" />
      </geometry>
    </collision>
    <visual>
      <origin rpy="0 0 0" xyz="0 0 0" />
      <geometry>
        <mesh filename="package://irb140_layout/meshes/gripper/mesh_dedo.stl" scale="0.001 0.001 0.001" />
      </geometry>
      <material name="white">
        <color rgba="1 1 1 1" />
      </material>
    </visual>
  </link>
  <joint name="right_ext__right_finger" type="fixed">
    <origin rpy="0 0 0" xyz="0 0 0.080" />
    <parent link="right_ext" />
    <child link="right_finger" />
  </joint>

  <!-- TCP -->
  <link name="tcp_link"></link>
  <joint name="tcp_joint" type="fixed">
		<parent link="link_6" />
		<child link="tcp_link" />
		<origin rpy="0 1.57 0" xyz="0.25 0 0" />
	</joint>

  <!-- Gazebo plugin for ROS Control -->
  <gazebo>
    <plugin name="gazebo_ros_control" filename="libgazebo_ros_control.so">
      <robotSimType>gazebo_ros_control/DefaultRobotHWSim</robotSimType >
    </plugin>
  </gazebo>
  <!-- Base -->
  <gazebo reference="base_link">
    <material>Gazebo/Orange</material>
  </gazebo>

  <!-- Link1 -->
  <gazebo reference="link_1">
    <material>Gazebo/Orange</material>
  </gazebo>

  <!-- Link2 -->
  <gazebo reference="link_2">
    <material>Gazebo/Orange</material>
  </gazebo>

  <!-- Link3 -->
  <gazebo reference="link_3">
    <material>Gazebo/Orange</material>
  </gazebo>

  <!-- Link4 -->
  <gazebo reference="link_4">
    <material>Gazebo/Orange</material>
  </gazebo>

  <!-- Link5 -->
  <gazebo reference="link_5">
    <material>Gazebo/Orange</material>
  </gazebo>

  <!-- Link6 -->
  <gazebo reference="link_6">
    <material>Gazebo/Orange</material>
  </gazebo>

  <!-- Base -->
  <gazebo reference="gripper_body">
    <material>Gazebo/DarkGrey</material>
  </gazebo>

  <!-- Dedos -->
  <gazebo reference="left_ext">
    <material>Gazebo/Red</material>
  </gazebo>
  <gazebo reference="right_ext">
    <material>Gazebo/Red</material>
  </gazebo>
  <gazebo reference="right_int">
    <material>Gazebo/Blue</material>
  </gazebo>
  <gazebo reference="left_int">
    <material>Gazebo/Blue</material>
  </gazebo>

</robot>